<?xml version="1.0" ?>
<robot name="al5d_arm">
	<link name="base_link">
		<visual>
			<geometry>
				<cylinder length="0.056" radius="0.0475"/>
			</geometry>
			<material name="black">
				<color rgba="0 0 0 1"/>
			</material>
		</visual>
	<collision>
		<geometry>
			<cylinder length="0.056" radius="0.0475"/>
		</geometry>
		<material name="green">
			<color rgba="0 1 0 1"/>
		</material>
	</collision>
	</link>

	<joint name="base_joint" type="revolute">
		<parent link="base_link" />
		<child link="shoulder_servo_link" />
		<origin xyz="0 0 0.0465" rpy="0 0 0" /> 
		<axis xyz="0 0 1" />
		<limit lower="-1.57" upper="1.57" effort="10" velocity="3" />	
	</joint>

	<link name="shoulder_servo_link">
		<visual>
			<geometry>
				<box size="0.061 0.082 0.037" />
			</geometry>
			<material name="gray">
				<color rgba="0.5 0.5 0.5 1"/>
			</material>
			<origin xyz="0 0 0"/>
		</visual>
		<collision>
			<geometry>
				<box size="0.061 0.082 0.037" />
			</geometry>
			<material name="blue">
				<color rgba="0 0 1 1"/>
			</material>
			<origin xyz="0 0 0"/>
		</collision>
	</link>

	<joint name="shoulder_joint" type="revolute">
		<parent link="shoulder_servo_link" />
		<child link="upper_arm" />
		<axis xyz="0 1 0" rpy="0 0 0"/>
		<limit lower="-1.553" upper="1.553" effort="0" velocity="3" />
	</joint>

	<link name="upper_arm">
		<visual>
			<geometry>
				<box size="0.024 0.078 0.18" />
			</geometry>
			<material name="gray"/>
			<origin xyz="0 0 0.086"/>
		</visual>
		<collision>
			<geometry>
				<box size="0.024 0.078 0.18" />
			</geometry>
			<material name="blue"/>
			<origin xyz="0 0 0.086"/>
		</collision>
	</link>

	<joint name="elbow" type="revolute">
		<parent link="upper_arm" />
		<child link="forearm" />
		<origin xyz="0 0 0.167" rpy="0 0 0" />
		<axis xyz="0 1 0" rpy="0 0 0"/>
		<limit lower="-1.57" upper="1.57" effort="10" velocity="3" />
	</joint>

	<link name="forearm">
		<visual>
			<geometry>
				<box size="0.078 0.070 0.034 " />
			</geometry>
			<material name="gray"/>
			<origin xyz="-0.0145 0 0"/>
		</visual>	
		<collision>
		<geometry>
				<box size="0.078 0.070 0.034 " />
			</geometry>
			<material name="gray"/>
			<origin xyz="-0.0145 0 0"/>	
		</collision>

		<visual>
			<geometry>
				<box size="0.181 0.054 0.026" />
			</geometry>
			<material name="gray" />
			<!-- half of own length + half of other box length - origin of other box -->
			<origin xyz="0.115 0 0"/>			
		</visual>
		<collision>
			<geometry>
				<box size="0.181 0.054 0.026" />
			</geometry>
			<material name="gray" />
			<!-- half of own length + half of other box length - origin of other box -->
			<origin xyz="0.115 0 0"/>		
		</collision>
	</link>

	<joint name="wrist" type="revolute">
		<parent link="forearm"/>
		<child link="hand"/>
		<origin xyz="0.189 0 0"/>
		<axis xyz="0 1 0" rpy="0 0 0"/>
		<limit lower="-1.57" upper="1.57" effort="10" velocity="3" />
	</joint>

	<link name="hand">
		<visual>
			<geometry>
				<box size="0.063 0.078 0.024 " />
			</geometry>
			<material name="gray" />
			<origin xyz="0.0196 0 0"/>
		</visual>
		<collision>
			<geometry>
				<box size="0.063 0.078 0.024 " />
			</geometry>
			<material name="red">
				<color rgba="1 0 0 1"/>
			</material>
			<origin xyz="0.0196 0 0"/>
		</collision>
	</link>

	<joint name="wrist_rotate" type="revolute">
		<parent link="hand"/>
		<child link="finger_base"/>
		<origin xyz="0.07 0 0"/>
		<axis xyz="1 0 0" rpy="0 0 0"/>
		<limit lower="-1.57" upper="1.57" effort="10" velocity="3" />
	</joint>

	<link name="finger_base">
		<visual>
			<geometry>
				<box size="0.0385 0.065 0.0195 " />
			</geometry>
			<material name="gray"/>
			<origin xyz="0 0 0"/>
		</visual>
		<collision>
			<geometry>
				<box size="0.0385 0.065 0.0195 " />
			</geometry>
		</collision>
	</link>

<joint name="left_gripper" type="prismatic">
		<parent link="finger_base" />
		<child link="left_finger" />
		<!-- y origin is (parent_y/2 - child_y/2) * -1-->
		<origin xyz="0.0335 0.02375 0" rpy="0 0 0" />
		<axis xyz="0 1 0" rpy="0 0 0"/>
		<limit lower="-0.017" upper="0" effort="10" velocity="3" />	
	</joint>

	<link name="left_finger">
		<visual>
			<geometry>
				<box size="0.0285 0.0135 0.019 " />
			</geometry>
			<material name="gray"/>
			<origin xyz="0 0 0"/>
		</visual>
		<collision>
			<geometry>
				<box size="0.0285 0.0135 0.019 " />
			</geometry>
		</collision>
	</link>

	<joint name="right_gripper" type="prismatic">
		<parent link="finger_base" />
		<child link="right_finger" />
		<!-- y origin is parent_y/2 - child_y/2 -->
		<origin xyz="0.0335 -0.02375 0" rpy="0 0 0" />
		<axis xyz="0 1 0" rpy="0 0 0"/>
		<!-- <limit lower="89" upper="-89" effort="10" velocity="3" />	 -->
		<limit lower="-0.017" upper="0" effort="10" velocity="3" />
		<mimic joint="left_gripper" multiplier="-1" />
	</joint>

	<link name="right_finger">
		<visual>
			<geometry>
				<box size="0.0285 0.0135 0.019 " />
			</geometry>
			<material name="gray" />
			<origin xyz="0 0 0"/>
		</visual>
		<collision>
			<geometry>
				<box size="0.0285 0.0135 0.019 " />
			</geometry>
		</collision>
	</link>

<!--
	<joint name="kinect_to_thumper" type="fixed">
		<parent link="base_link" />
		<child link="camera_link" />
		<origin xyz="0 0 0.30" rpy="0 0 0" />
	</joint>

	<link name="camera_link">
		<visual>
			<geometry>
				<box size="0.06 0.2 0.04" />
			</geometry>
			<material name="green">
				<color rgba="0 1 0 1"/>
			</material>
		</visual>
	</link>
-->

</robot>